<?xml version="1.0"?>
<robot name="planar_30_dof_robot">
    <!-- Materials -->
    <material name="blue">
        <color rgba="0.0 0.0 0.8 1.0"/>
    </material>
    <material name="red">
        <color rgba="0.8 0.0 0.0 1.0"/>
    </material>
    <material name="green">
        <color rgba="0.0 0.8 0.0 1.0"/>
    </material>
    <material name="yellow">
        <color rgba="0.8 0.8 0.0 1.0"/>
    </material>
    <material name="purple">
        <color rgba="0.8 0.0 0.8 1.0"/>
    </material>
    <material name="cyan">
        <color rgba="0.0 0.8 0.8 1.0"/>
    </material>
    <material name="orange">
        <color rgba="1.0 0.5 0.0 1.0"/>
    </material>
    <material name="grey">
        <color rgba="0.5 0.5 0.5 1.0"/>
    </material>

    <!-- Base Link - flat on the floor -->
    <link name="base_link">
        <visual>
            <geometry>
                <box size="0.1 0.1 0.025"/>
            </geometry>
            <origin xyz="0 0 0.0125" rpy="0 0 0"/>
            <material name="grey"/>
        </visual>
        <collision>
            <geometry>
                <box size="0.1 0.1 0.025"/>
            </geometry>
            <origin xyz="0 0 0.0125" rpy="0 0 0"/>
        </collision>
        <inertial>
            <mass value="1.0"/>
            <origin xyz="0 0 0.0125" rpy="0 0 0"/>
            <inertia 
                ixx="0.0008854166666666668" 
                ixy="0" ixz="0" 
                iyy="0.0008854166666666668" 
                iyz="0" 
                izz="0.001666666666666667"/>
        </inertial>
    </link>

    <!-- Joint 1: base_link to link1 (Revolute around Z-axis) -->
    <joint name="joint1" type="revolute">
        <parent link="base_link"/>
        <child link="link1"/>
        <origin xyz="0.05 0 0" rpy="0 0 0"/>
        <axis xyz="0 0 1"/>
        <limit lower="-3.14" upper="3.14" effort="100" velocity="1.0"/>
    </joint>

    <!-- Link 1 - flat on the floor -->
    <link name="link1">
        <visual>
            <geometry>
                <box size="0.03333333333333333 0.013333333333333334 0.025"/>
            </geometry>
            <origin xyz="0.016666666666666666 0 0.0125" rpy="0 0 0"/>
            <material name="blue"/>
        </visual>
        <collision>
            <geometry>
                <box size="0.03333333333333333 0.013333333333333334 0.025"/>
            </geometry>
            <origin xyz="0.016666666666666666 0 0.0125" rpy="0 0 0"/>
        </collision>
        <inertial>
            <mass value="1.000"/>
            <origin xyz="0.016666666666666666 0 0.0125" rpy="0 0 0"/>
            <inertia ixx="0.000067" ixy="0" ixz="0" iyy="0.000145" iyz="0" izz="0.000107"/>
        </inertial>
    </link>

    <!-- Joint 2: link1 to link2 (Revolute around Z-axis) -->
    <joint name="joint2" type="revolute">
        <parent link="link1"/>
        <child link="link2"/>
        <origin xyz="0.03333333333333333 0 0" rpy="0 0 0"/>
        <axis xyz="0 0 1"/>
        <limit lower="-3.14" upper="3.14" effort="100.0" velocity="1.0"/>
    </joint>

    <!-- Link 2 - flat on the floor -->
    <link name="link2">
        <visual>
            <geometry>
                <box size="0.03333333333333333 0.013333333333333334 0.025"/>
            </geometry>
            <origin xyz="0.016666666666666666 0 0.0125" rpy="0 0 0"/>
            <material name="red"/>
        </visual>
        <collision>
            <geometry>
                <box size="0.03333333333333333 0.013333333333333334 0.025"/>
            </geometry>
            <origin xyz="0.016666666666666666 0 0.0125" rpy="0 0 0"/>
        </collision>
        <inertial>
            <mass value="0.997"/>
            <origin xyz="0.016666666666666666 0 0.0125" rpy="0 0 0"/>
            <inertia ixx="0.000067" ixy="0" ixz="0" iyy="0.000144" iyz="0" izz="0.000107"/>
        </inertial>
    </link>

    <!-- Joint 3: link2 to link3 (Revolute around Z-axis) -->
    <joint name="joint3" type="revolute">
        <parent link="link2"/>
        <child link="link3"/>
        <origin xyz="0.03333333333333333 0 0" rpy="0 0 0"/>
        <axis xyz="0 0 1"/>
        <limit lower="-3.14" upper="3.14" effort="66.66666666666667" velocity="1.0"/>
    </joint>

    <!-- Link 3 - flat on the floor -->
    <link name="link3">
        <visual>
            <geometry>
                <box size="0.03333333333333333 0.013333333333333334 0.025"/>
            </geometry>
            <origin xyz="0.016666666666666666 0 0.0125" rpy="0 0 0"/>
            <material name="green"/>
        </visual>
        <collision>
            <geometry>
                <box size="0.03333333333333333 0.013333333333333334 0.025"/>
            </geometry>
            <origin xyz="0.016666666666666666 0 0.0125" rpy="0 0 0"/>
        </collision>
        <inertial>
            <mass value="0.993"/>
            <origin xyz="0.016666666666666666 0 0.0125" rpy="0 0 0"/>
            <inertia ixx="0.000066" ixy="0" ixz="0" iyy="0.000144" iyz="0" izz="0.000107"/>
        </inertial>
    </link>

    <!-- Joint 4: link3 to link4 (Revolute around Z-axis) -->
    <joint name="joint4" type="revolute">
        <parent link="link3"/>
        <child link="link4"/>
        <origin xyz="0.03333333333333333 0 0" rpy="0 0 0"/>
        <axis xyz="0 0 1"/>
        <limit lower="-3.14" upper="3.14" effort="50.0" velocity="1.0"/>
    </joint>

    <!-- Link 4 - flat on the floor -->
    <link name="link4">
        <visual>
            <geometry>
                <box size="0.03333333333333333 0.013333333333333334 0.025"/>
            </geometry>
            <origin xyz="0.016666666666666666 0 0.0125" rpy="0 0 0"/>
            <material name="yellow"/>
        </visual>
        <collision>
            <geometry>
                <box size="0.03333333333333333 0.013333333333333334 0.025"/>
            </geometry>
            <origin xyz="0.016666666666666666 0 0.0125" rpy="0 0 0"/>
        </collision>
        <inertial>
            <mass value="0.990"/>
            <origin xyz="0.016666666666666666 0 0.0125" rpy="0 0 0"/>
            <inertia ixx="0.000066" ixy="0" ixz="0" iyy="0.000143" iyz="0" izz="0.000106"/>
        </inertial>
    </link>

    <!-- Joint 5: link4 to link5 (Revolute around Z-axis) -->
    <joint name="joint5" type="revolute">
        <parent link="link4"/>
        <child link="link5"/>
        <origin xyz="0.03333333333333333 0 0" rpy="0 0 0"/>
        <axis xyz="0 0 1"/>
        <limit lower="-3.14" upper="3.14" effort="40.0" velocity="1.0"/>
    </joint>

    <!-- Link 5 - flat on the floor -->
    <link name="link5">
        <visual>
            <geometry>
                <box size="0.03333333333333333 0.013333333333333334 0.025"/>
            </geometry>
            <origin xyz="0.016666666666666666 0 0.0125" rpy="0 0 0"/>
            <material name="purple"/>
        </visual>
        <collision>
            <geometry>
                <box size="0.03333333333333333 0.013333333333333334 0.025"/>
            </geometry>
            <origin xyz="0.016666666666666666 0 0.0125" rpy="0 0 0"/>
        </collision>
        <inertial>
            <mass value="0.987"/>
            <origin xyz="0.016666666666666666 0 0.0125" rpy="0 0 0"/>
            <inertia ixx="0.000066" ixy="0" ixz="0" iyy="0.000143" iyz="0" izz="0.000106"/>
        </inertial>
    </link>

    <!-- Joint 6: link5 to link6 (Revolute around Z-axis) -->
    <joint name="joint6" type="revolute">
        <parent link="link5"/>
        <child link="link6"/>
        <origin xyz="0.03333333333333333 0 0" rpy="0 0 0"/>
        <axis xyz="0 0 1"/>
        <limit lower="-3.14" upper="3.14" effort="33.333333333333336" velocity="1.0"/>
    </joint>

    <!-- Link 6 - flat on the floor -->
    <link name="link6">
        <visual>
            <geometry>
                <box size="0.03333333333333333 0.013333333333333334 0.025"/>
            </geometry>
            <origin xyz="0.016666666666666666 0 0.0125" rpy="0 0 0"/>
            <material name="cyan"/>
        </visual>
        <collision>
            <geometry>
                <box size="0.03333333333333333 0.013333333333333334 0.025"/>
            </geometry>
            <origin xyz="0.016666666666666666 0 0.0125" rpy="0 0 0"/>
        </collision>
        <inertial>
            <mass value="0.983"/>
            <origin xyz="0.016666666666666666 0 0.0125" rpy="0 0 0"/>
            <inertia ixx="0.000066" ixy="0" ixz="0" iyy="0.000142" iyz="0" izz="0.000106"/>
        </inertial>
    </link>

    <!-- Joint 7: link6 to link7 (Revolute around Z-axis) -->
    <joint name="joint7" type="revolute">
        <parent link="link6"/>
        <child link="link7"/>
        <origin xyz="0.03333333333333333 0 0" rpy="0 0 0"/>
        <axis xyz="0 0 1"/>
        <limit lower="-3.14" upper="3.14" effort="28.571428571428573" velocity="1.0"/>
    </joint>

    <!-- Link 7 - flat on the floor -->
    <link name="link7">
        <visual>
            <geometry>
                <box size="0.03333333333333333 0.013333333333333334 0.025"/>
            </geometry>
            <origin xyz="0.016666666666666666 0 0.0125" rpy="0 0 0"/>
            <material name="orange"/>
        </visual>
        <collision>
            <geometry>
                <box size="0.03333333333333333 0.013333333333333334 0.025"/>
            </geometry>
            <origin xyz="0.016666666666666666 0 0.0125" rpy="0 0 0"/>
        </collision>
        <inertial>
            <mass value="0.980"/>
            <origin xyz="0.016666666666666666 0 0.0125" rpy="0 0 0"/>
            <inertia ixx="0.000066" ixy="0" ixz="0" iyy="0.000142" iyz="0" izz="0.000105"/>
        </inertial>
    </link>

    <!-- Joint 8: link7 to link8 (Revolute around Z-axis) -->
    <joint name="joint8" type="revolute">
        <parent link="link7"/>
        <child link="link8"/>
        <origin xyz="0.03333333333333333 0 0" rpy="0 0 0"/>
        <axis xyz="0 0 1"/>
        <limit lower="-3.14" upper="3.14" effort="25.0" velocity="1.0"/>
    </joint>

    <!-- Link 8 - flat on the floor -->
    <link name="link8">
        <visual>
            <geometry>
                <box size="0.03333333333333333 0.013333333333333334 0.025"/>
            </geometry>
            <origin xyz="0.016666666666666666 0 0.0125" rpy="0 0 0"/>
            <material name="grey"/>
        </visual>
        <collision>
            <geometry>
                <box size="0.03333333333333333 0.013333333333333334 0.025"/>
            </geometry>
            <origin xyz="0.016666666666666666 0 0.0125" rpy="0 0 0"/>
        </collision>
        <inertial>
            <mass value="0.977"/>
            <origin xyz="0.016666666666666666 0 0.0125" rpy="0 0 0"/>
            <inertia ixx="0.000065" ixy="0" ixz="0" iyy="0.000141" iyz="0" izz="0.000105"/>
        </inertial>
    </link>

    <!-- Joint 9: link8 to link9 (Revolute around Z-axis) -->
    <joint name="joint9" type="revolute">
        <parent link="link8"/>
        <child link="link9"/>
        <origin xyz="0.03333333333333333 0 0" rpy="0 0 0"/>
        <axis xyz="0 0 1"/>
        <limit lower="-3.14" upper="3.14" effort="22.22222222222222" velocity="1.0"/>
    </joint>

    <!-- Link 9 - flat on the floor -->
    <link name="link9">
        <visual>
            <geometry>
                <box size="0.03333333333333333 0.013333333333333334 0.025"/>
            </geometry>
            <origin xyz="0.016666666666666666 0 0.0125" rpy="0 0 0"/>
            <material name="blue"/>
        </visual>
        <collision>
            <geometry>
                <box size="0.03333333333333333 0.013333333333333334 0.025"/>
            </geometry>
            <origin xyz="0.016666666666666666 0 0.0125" rpy="0 0 0"/>
        </collision>
        <inertial>
            <mass value="0.973"/>
            <origin xyz="0.016666666666666666 0 0.0125" rpy="0 0 0"/>
            <inertia ixx="0.000065" ixy="0" ixz="0" iyy="0.000141" iyz="0" izz="0.000105"/>
        </inertial>
    </link>

    <!-- Joint 10: link9 to link10 (Revolute around Z-axis) -->
    <joint name="joint10" type="revolute">
        <parent link="link9"/>
        <child link="link10"/>
        <origin xyz="0.03333333333333333 0 0" rpy="0 0 0"/>
        <axis xyz="0 0 1"/>
        <limit lower="-3.14" upper="3.14" effort="20.0" velocity="1.0"/>
    </joint>

    <!-- Link 10 - flat on the floor -->
    <link name="link10">
        <visual>
            <geometry>
                <box size="0.03333333333333333 0.013333333333333334 0.025"/>
            </geometry>
            <origin xyz="0.016666666666666666 0 0.0125" rpy="0 0 0"/>
            <material name="red"/>
        </visual>
        <collision>
            <geometry>
                <box size="0.03333333333333333 0.013333333333333334 0.025"/>
            </geometry>
            <origin xyz="0.016666666666666666 0 0.0125" rpy="0 0 0"/>
        </collision>
        <inertial>
            <mass value="0.970"/>
            <origin xyz="0.016666666666666666 0 0.0125" rpy="0 0 0"/>
            <inertia ixx="0.000065" ixy="0" ixz="0" iyy="0.000140" iyz="0" izz="0.000104"/>
        </inertial>
    </link>

    <!-- Joint 11: link10 to link11 (Revolute around Z-axis) -->
    <joint name="joint11" type="revolute">
        <parent link="link10"/>
        <child link="link11"/>
        <origin xyz="0.03333333333333333 0 0" rpy="0 0 0"/>
        <axis xyz="0 0 1"/>
        <limit lower="-3.14" upper="3.14" effort="18.181818181818183" velocity="1.0"/>
    </joint>

    <!-- Link 11 - flat on the floor -->
    <link name="link11">
        <visual>
            <geometry>
                <box size="0.03333333333333333 0.013333333333333334 0.025"/>
            </geometry>
            <origin xyz="0.016666666666666666 0 0.0125" rpy="0 0 0"/>
            <material name="green"/>
        </visual>
        <collision>
            <geometry>
                <box size="0.03333333333333333 0.013333333333333334 0.025"/>
            </geometry>
            <origin xyz="0.016666666666666666 0 0.0125" rpy="0 0 0"/>
        </collision>
        <inertial>
            <mass value="0.967"/>
            <origin xyz="0.016666666666666666 0 0.0125" rpy="0 0 0"/>
            <inertia ixx="0.000065" ixy="0" ixz="0" iyy="0.000140" iyz="0" izz="0.000104"/>
        </inertial>
    </link>

    <!-- Joint 12: link11 to link12 (Revolute around Z-axis) -->
    <joint name="joint12" type="revolute">
        <parent link="link11"/>
        <child link="link12"/>
        <origin xyz="0.03333333333333333 0 0" rpy="0 0 0"/>
        <axis xyz="0 0 1"/>
        <limit lower="-3.14" upper="3.14" effort="16.666666666666668" velocity="1.0"/>
    </joint>

    <!-- Link 12 - flat on the floor -->
    <link name="link12">
        <visual>
            <geometry>
                <box size="0.03333333333333333 0.013333333333333334 0.025"/>
            </geometry>
            <origin xyz="0.016666666666666666 0 0.0125" rpy="0 0 0"/>
            <material name="yellow"/>
        </visual>
        <collision>
            <geometry>
                <box size="0.03333333333333333 0.013333333333333334 0.025"/>
            </geometry>
            <origin xyz="0.016666666666666666 0 0.0125" rpy="0 0 0"/>
        </collision>
        <inertial>
            <mass value="0.963"/>
            <origin xyz="0.016666666666666666 0 0.0125" rpy="0 0 0"/>
            <inertia ixx="0.000064" ixy="0" ixz="0" iyy="0.000139" iyz="0" izz="0.000103"/>
        </inertial>
    </link>

    <!-- Joint 13: link12 to link13 (Revolute around Z-axis) -->
    <joint name="joint13" type="revolute">
        <parent link="link12"/>
        <child link="link13"/>
        <origin xyz="0.03333333333333333 0 0" rpy="0 0 0"/>
        <axis xyz="0 0 1"/>
        <limit lower="-3.14" upper="3.14" effort="15.384615384615385" velocity="1.0"/>
    </joint>

    <!-- Link 13 - flat on the floor -->
    <link name="link13">
        <visual>
            <geometry>
                <box size="0.03333333333333333 0.013333333333333334 0.025"/>
            </geometry>
            <origin xyz="0.016666666666666666 0 0.0125" rpy="0 0 0"/>
            <material name="purple"/>
        </visual>
        <collision>
            <geometry>
                <box size="0.03333333333333333 0.013333333333333334 0.025"/>
            </geometry>
            <origin xyz="0.016666666666666666 0 0.0125" rpy="0 0 0"/>
        </collision>
        <inertial>
            <mass value="0.960"/>
            <origin xyz="0.016666666666666666 0 0.0125" rpy="0 0 0"/>
            <inertia ixx="0.000064" ixy="0" ixz="0" iyy="0.000139" iyz="0" izz="0.000103"/>
        </inertial>
    </link>

    <!-- Joint 14: link13 to link14 (Revolute around Z-axis) -->
    <joint name="joint14" type="revolute">
        <parent link="link13"/>
        <child link="link14"/>
        <origin xyz="0.03333333333333333 0 0" rpy="0 0 0"/>
        <axis xyz="0 0 1"/>
        <limit lower="-3.14" upper="3.14" effort="14.285714285714286" velocity="1.0"/>
    </joint>

    <!-- Link 14 - flat on the floor -->
    <link name="link14">
        <visual>
            <geometry>
                <box size="0.03333333333333333 0.013333333333333334 0.025"/>
            </geometry>
            <origin xyz="0.016666666666666666 0 0.0125" rpy="0 0 0"/>
            <material name="cyan"/>
        </visual>
        <collision>
            <geometry>
                <box size="0.03333333333333333 0.013333333333333334 0.025"/>
            </geometry>
            <origin xyz="0.016666666666666666 0 0.0125" rpy="0 0 0"/>
        </collision>
        <inertial>
            <mass value="0.957"/>
            <origin xyz="0.016666666666666666 0 0.0125" rpy="0 0 0"/>
            <inertia ixx="0.000064" ixy="0" ixz="0" iyy="0.000138" iyz="0" izz="0.000103"/>
        </inertial>
    </link>

    <!-- Joint 15: link14 to link15 (Revolute around Z-axis) -->
    <joint name="joint15" type="revolute">
        <parent link="link14"/>
        <child link="link15"/>
        <origin xyz="0.03333333333333333 0 0" rpy="0 0 0"/>
        <axis xyz="0 0 1"/>
        <limit lower="-3.14" upper="3.14" effort="13.333333333333334" velocity="1.0"/>
    </joint>

    <!-- Link 15 - flat on the floor -->
    <link name="link15">
        <visual>
            <geometry>
                <box size="0.03333333333333333 0.013333333333333334 0.025"/>
            </geometry>
            <origin xyz="0.016666666666666666 0 0.0125" rpy="0 0 0"/>
            <material name="orange"/>
        </visual>
        <collision>
            <geometry>
                <box size="0.03333333333333333 0.013333333333333334 0.025"/>
            </geometry>
            <origin xyz="0.016666666666666666 0 0.0125" rpy="0 0 0"/>
        </collision>
        <inertial>
            <mass value="0.953"/>
            <origin xyz="0.016666666666666666 0 0.0125" rpy="0 0 0"/>
            <inertia ixx="0.000064" ixy="0" ixz="0" iyy="0.000138" iyz="0" izz="0.000102"/>
        </inertial>
    </link>

    <!-- Joint 16: link15 to link16 (Revolute around Z-axis) -->
    <joint name="joint16" type="revolute">
        <parent link="link15"/>
        <child link="link16"/>
        <origin xyz="0.03333333333333333 0 0" rpy="0 0 0"/>
        <axis xyz="0 0 1"/>
        <limit lower="-3.14" upper="3.14" effort="12.5" velocity="1.0"/>
    </joint>

    <!-- Link 16 - flat on the floor -->
    <link name="link16">
        <visual>
            <geometry>
                <box size="0.03333333333333333 0.013333333333333334 0.025"/>
            </geometry>
            <origin xyz="0.016666666666666666 0 0.0125" rpy="0 0 0"/>
            <material name="grey"/>
        </visual>
        <collision>
            <geometry>
                <box size="0.03333333333333333 0.013333333333333334 0.025"/>
            </geometry>
            <origin xyz="0.016666666666666666 0 0.0125" rpy="0 0 0"/>
        </collision>
        <inertial>
            <mass value="0.950"/>
            <origin xyz="0.016666666666666666 0 0.0125" rpy="0 0 0"/>
            <inertia ixx="0.000064" ixy="0" ixz="0" iyy="0.000137" iyz="0" izz="0.000102"/>
        </inertial>
    </link>

    <!-- Joint 17: link16 to link17 (Revolute around Z-axis) -->
    <joint name="joint17" type="revolute">
        <parent link="link16"/>
        <child link="link17"/>
        <origin xyz="0.03333333333333333 0 0" rpy="0 0 0"/>
        <axis xyz="0 0 1"/>
        <limit lower="-3.14" upper="3.14" effort="11.764705882352942" velocity="1.0"/>
    </joint>

    <!-- Link 17 - flat on the floor -->
    <link name="link17">
        <visual>
            <geometry>
                <box size="0.03333333333333333 0.013333333333333334 0.025"/>
            </geometry>
            <origin xyz="0.016666666666666666 0 0.0125" rpy="0 0 0"/>
            <material name="blue"/>
        </visual>
        <collision>
            <geometry>
                <box size="0.03333333333333333 0.013333333333333334 0.025"/>
            </geometry>
            <origin xyz="0.016666666666666666 0 0.0125" rpy="0 0 0"/>
        </collision>
        <inertial>
            <mass value="0.947"/>
            <origin xyz="0.016666666666666666 0 0.0125" rpy="0 0 0"/>
            <inertia ixx="0.000063" ixy="0" ixz="0" iyy="0.000137" iyz="0" izz="0.000102"/>
        </inertial>
    </link>

    <!-- Joint 18: link17 to link18 (Revolute around Z-axis) -->
    <joint name="joint18" type="revolute">
        <parent link="link17"/>
        <child link="link18"/>
        <origin xyz="0.03333333333333333 0 0" rpy="0 0 0"/>
        <axis xyz="0 0 1"/>
        <limit lower="-3.14" upper="3.14" effort="11.11111111111111" velocity="1.0"/>
    </joint>

    <!-- Link 18 - flat on the floor -->
    <link name="link18">
        <visual>
            <geometry>
                <box size="0.03333333333333333 0.013333333333333334 0.025"/>
            </geometry>
            <origin xyz="0.016666666666666666 0 0.0125" rpy="0 0 0"/>
            <material name="red"/>
        </visual>
        <collision>
            <geometry>
                <box size="0.03333333333333333 0.013333333333333334 0.025"/>
            </geometry>
            <origin xyz="0.016666666666666666 0 0.0125" rpy="0 0 0"/>
        </collision>
        <inertial>
            <mass value="0.943"/>
            <origin xyz="0.016666666666666666 0 0.0125" rpy="0 0 0"/>
            <inertia ixx="0.000063" ixy="0" ixz="0" iyy="0.000136" iyz="0" izz="0.000101"/>
        </inertial>
    </link>

    <!-- Joint 19: link18 to link19 (Revolute around Z-axis) -->
    <joint name="joint19" type="revolute">
        <parent link="link18"/>
        <child link="link19"/>
        <origin xyz="0.03333333333333333 0 0" rpy="0 0 0"/>
        <axis xyz="0 0 1"/>
        <limit lower="-3.14" upper="3.14" effort="10.526315789473685" velocity="1.0"/>
    </joint>

    <!-- Link 19 - flat on the floor -->
    <link name="link19">
        <visual>
            <geometry>
                <box size="0.03333333333333333 0.013333333333333334 0.025"/>
            </geometry>
            <origin xyz="0.016666666666666666 0 0.0125" rpy="0 0 0"/>
            <material name="green"/>
        </visual>
        <collision>
            <geometry>
                <box size="0.03333333333333333 0.013333333333333334 0.025"/>
            </geometry>
            <origin xyz="0.016666666666666666 0 0.0125" rpy="0 0 0"/>
        </collision>
        <inertial>
            <mass value="0.940"/>
            <origin xyz="0.016666666666666666 0 0.0125" rpy="0 0 0"/>
            <inertia ixx="0.000063" ixy="0" ixz="0" iyy="0.000136" iyz="0" izz="0.000101"/>
        </inertial>
    </link>

    <!-- Joint 20: link19 to link20 (Revolute around Z-axis) -->
    <joint name="joint20" type="revolute">
        <parent link="link19"/>
        <child link="link20"/>
        <origin xyz="0.03333333333333333 0 0" rpy="0 0 0"/>
        <axis xyz="0 0 1"/>
        <limit lower="-3.14" upper="3.14" effort="10.0" velocity="1.0"/>
    </joint>

    <!-- Link 20 - flat on the floor -->
    <link name="link20">
        <visual>
            <geometry>
                <box size="0.03333333333333333 0.013333333333333334 0.025"/>
            </geometry>
            <origin xyz="0.016666666666666666 0 0.0125" rpy="0 0 0"/>
            <material name="yellow"/>
        </visual>
        <collision>
            <geometry>
                <box size="0.03333333333333333 0.013333333333333334 0.025"/>
            </geometry>
            <origin xyz="0.016666666666666666 0 0.0125" rpy="0 0 0"/>
        </collision>
        <inertial>
            <mass value="0.937"/>
            <origin xyz="0.016666666666666666 0 0.0125" rpy="0 0 0"/>
            <inertia ixx="0.000063" ixy="0" ixz="0" iyy="0.000136" iyz="0" izz="0.000101"/>
        </inertial>
    </link>

    <!-- Joint 21: link20 to link21 (Revolute around Z-axis) -->
    <joint name="joint21" type="revolute">
        <parent link="link20"/>
        <child link="link21"/>
        <origin xyz="0.03333333333333333 0 0" rpy="0 0 0"/>
        <axis xyz="0 0 1"/>
        <limit lower="-3.14" upper="3.14" effort="9.523809523809524" velocity="1.0"/>
    </joint>

    <!-- Link 21 - flat on the floor -->
    <link name="link21">
        <visual>
            <geometry>
                <box size="0.03333333333333333 0.013333333333333334 0.025"/>
            </geometry>
            <origin xyz="0.016666666666666666 0 0.0125" rpy="0 0 0"/>
            <material name="purple"/>
        </visual>
        <collision>
            <geometry>
                <box size="0.03333333333333333 0.013333333333333334 0.025"/>
            </geometry>
            <origin xyz="0.016666666666666666 0 0.0125" rpy="0 0 0"/>
        </collision>
        <inertial>
            <mass value="0.933"/>
            <origin xyz="0.016666666666666666 0 0.0125" rpy="0 0 0"/>
            <inertia ixx="0.000062" ixy="0" ixz="0" iyy="0.000135" iyz="0" izz="0.000100"/>
        </inertial>
    </link>

    <!-- Joint 22: link21 to link22 (Revolute around Z-axis) -->
    <joint name="joint22" type="revolute">
        <parent link="link21"/>
        <child link="link22"/>
        <origin xyz="0.03333333333333333 0 0" rpy="0 0 0"/>
        <axis xyz="0 0 1"/>
        <limit lower="-3.14" upper="3.14" effort="9.090909090909092" velocity="1.0"/>
    </joint>

    <!-- Link 22 - flat on the floor -->
    <link name="link22">
        <visual>
            <geometry>
                <box size="0.03333333333333333 0.013333333333333334 0.025"/>
            </geometry>
            <origin xyz="0.016666666666666666 0 0.0125" rpy="0 0 0"/>
            <material name="cyan"/>
        </visual>
        <collision>
            <geometry>
                <box size="0.03333333333333333 0.013333333333333334 0.025"/>
            </geometry>
            <origin xyz="0.016666666666666666 0 0.0125" rpy="0 0 0"/>
        </collision>
        <inertial>
            <mass value="0.930"/>
            <origin xyz="0.016666666666666666 0 0.0125" rpy="0 0 0"/>
            <inertia ixx="0.000062" ixy="0" ixz="0" iyy="0.000135" iyz="0" izz="0.000100"/>
        </inertial>
    </link>

    <!-- Joint 23: link22 to link23 (Revolute around Z-axis) -->
    <joint name="joint23" type="revolute">
        <parent link="link22"/>
        <child link="link23"/>
        <origin xyz="0.03333333333333333 0 0" rpy="0 0 0"/>
        <axis xyz="0 0 1"/>
        <limit lower="-3.14" upper="3.14" effort="8.695652173913043" velocity="1.0"/>
    </joint>

    <!-- Link 23 - flat on the floor -->
    <link name="link23">
        <visual>
            <geometry>
                <box size="0.03333333333333333 0.013333333333333334 0.025"/>
            </geometry>
            <origin xyz="0.016666666666666666 0 0.0125" rpy="0 0 0"/>
            <material name="orange"/>
        </visual>
        <collision>
            <geometry>
                <box size="0.03333333333333333 0.013333333333333334 0.025"/>
            </geometry>
            <origin xyz="0.016666666666666666 0 0.0125" rpy="0 0 0"/>
        </collision>
        <inertial>
            <mass value="0.927"/>
            <origin xyz="0.016666666666666666 0 0.0125" rpy="0 0 0"/>
            <inertia ixx="0.000062" ixy="0" ixz="0" iyy="0.000134" iyz="0" izz="0.000100"/>
        </inertial>
    </link>

    <!-- Joint 24: link23 to link24 (Revolute around Z-axis) -->
    <joint name="joint24" type="revolute">
        <parent link="link23"/>
        <child link="link24"/>
        <origin xyz="0.03333333333333333 0 0" rpy="0 0 0"/>
        <axis xyz="0 0 1"/>
        <limit lower="-3.14" upper="3.14" effort="8.333333333333334" velocity="1.0"/>
    </joint>

    <!-- Link 24 - flat on the floor -->
    <link name="link24">
        <visual>
            <geometry>
                <box size="0.03333333333333333 0.013333333333333334 0.025"/>
            </geometry>
            <origin xyz="0.016666666666666666 0 0.0125" rpy="0 0 0"/>
            <material name="grey"/>
        </visual>
        <collision>
            <geometry>
                <box size="0.03333333333333333 0.013333333333333334 0.025"/>
            </geometry>
            <origin xyz="0.016666666666666666 0 0.0125" rpy="0 0 0"/>
        </collision>
        <inertial>
            <mass value="0.923"/>
            <origin xyz="0.016666666666666666 0 0.0125" rpy="0 0 0"/>
            <inertia ixx="0.000062" ixy="0" ixz="0" iyy="0.000134" iyz="0" izz="0.000099"/>
        </inertial>
    </link>

    <!-- Joint 25: link24 to link25 (Revolute around Z-axis) -->
    <joint name="joint25" type="revolute">
        <parent link="link24"/>
        <child link="link25"/>
        <origin xyz="0.03333333333333333 0 0" rpy="0 0 0"/>
        <axis xyz="0 0 1"/>
        <limit lower="-3.14" upper="3.14" effort="8.0" velocity="1.0"/>
    </joint>

    <!-- Link 25 - flat on the floor -->
    <link name="link25">
        <visual>
            <geometry>
                <box size="0.03333333333333333 0.013333333333333334 0.025"/>
            </geometry>
            <origin xyz="0.016666666666666666 0 0.0125" rpy="0 0 0"/>
            <material name="blue"/>
        </visual>
        <collision>
            <geometry>
                <box size="0.03333333333333333 0.013333333333333334 0.025"/>
            </geometry>
            <origin xyz="0.016666666666666666 0 0.0125" rpy="0 0 0"/>
        </collision>
        <inertial>
            <mass value="0.920"/>
            <origin xyz="0.016666666666666666 0 0.0125" rpy="0 0 0"/>
            <inertia ixx="0.000062" ixy="0" ixz="0" iyy="0.000133" iyz="0" izz="0.000099"/>
        </inertial>
    </link>

    <!-- Joint 26: link25 to link26 (Revolute around Z-axis) -->
    <joint name="joint26" type="revolute">
        <parent link="link25"/>
        <child link="link26"/>
        <origin xyz="0.03333333333333333 0 0" rpy="0 0 0"/>
        <axis xyz="0 0 1"/>
        <limit lower="-3.14" upper="3.14" effort="7.6923076923076925" velocity="1.0"/>
    </joint>

    <!-- Link 26 - flat on the floor -->
    <link name="link26">
        <visual>
            <geometry>
                <box size="0.03333333333333333 0.013333333333333334 0.025"/>
            </geometry>
            <origin xyz="0.016666666666666666 0 0.0125" rpy="0 0 0"/>
            <material name="red"/>
        </visual>
        <collision>
            <geometry>
                <box size="0.03333333333333333 0.013333333333333334 0.025"/>
            </geometry>
            <origin xyz="0.016666666666666666 0 0.0125" rpy="0 0 0"/>
        </collision>
        <inertial>
            <mass value="0.917"/>
            <origin xyz="0.016666666666666666 0 0.0125" rpy="0 0 0"/>
            <inertia ixx="0.000061" ixy="0" ixz="0" iyy="0.000133" iyz="0" izz="0.000098"/>
        </inertial>
    </link>

    <!-- Joint 27: link26 to link27 (Revolute around Z-axis) -->
    <joint name="joint27" type="revolute">
        <parent link="link26"/>
        <child link="link27"/>
        <origin xyz="0.03333333333333333 0 0" rpy="0 0 0"/>
        <axis xyz="0 0 1"/>
        <limit lower="-3.14" upper="3.14" effort="7.407407407407407" velocity="1.0"/>
    </joint>

    <!-- Link 27 - flat on the floor -->
    <link name="link27">
        <visual>
            <geometry>
                <box size="0.03333333333333333 0.013333333333333334 0.025"/>
            </geometry>
            <origin xyz="0.016666666666666666 0 0.0125" rpy="0 0 0"/>
            <material name="green"/>
        </visual>
        <collision>
            <geometry>
                <box size="0.03333333333333333 0.013333333333333334 0.025"/>
            </geometry>
            <origin xyz="0.016666666666666666 0 0.0125" rpy="0 0 0"/>
        </collision>
        <inertial>
            <mass value="0.913"/>
            <origin xyz="0.016666666666666666 0 0.0125" rpy="0 0 0"/>
            <inertia ixx="0.000061" ixy="0" ixz="0" iyy="0.000132" iyz="0" izz="0.000098"/>
        </inertial>
    </link>

    <!-- Joint 28: link27 to link28 (Revolute around Z-axis) -->
    <joint name="joint28" type="revolute">
        <parent link="link27"/>
        <child link="link28"/>
        <origin xyz="0.03333333333333333 0 0" rpy="0 0 0"/>
        <axis xyz="0 0 1"/>
        <limit lower="-3.14" upper="3.14" effort="7.142857142857143" velocity="1.0"/>
    </joint>

    <!-- Link 28 - flat on the floor -->
    <link name="link28">
        <visual>
            <geometry>
                <box size="0.03333333333333333 0.013333333333333334 0.025"/>
            </geometry>
            <origin xyz="0.016666666666666666 0 0.0125" rpy="0 0 0"/>
            <material name="yellow"/>
        </visual>
        <collision>
            <geometry>
                <box size="0.03333333333333333 0.013333333333333334 0.025"/>
            </geometry>
            <origin xyz="0.016666666666666666 0 0.0125" rpy="0 0 0"/>
        </collision>
        <inertial>
            <mass value="0.910"/>
            <origin xyz="0.016666666666666666 0 0.0125" rpy="0 0 0"/>
            <inertia ixx="0.000061" ixy="0" ixz="0" iyy="0.000132" iyz="0" izz="0.000098"/>
        </inertial>
    </link>

    <!-- Joint 29: link28 to link29 (Revolute around Z-axis) -->
    <joint name="joint29" type="revolute">
        <parent link="link28"/>
        <child link="link29"/>
        <origin xyz="0.03333333333333333 0 0" rpy="0 0 0"/>
        <axis xyz="0 0 1"/>
        <limit lower="-3.14" upper="3.14" effort="6.896551724137931" velocity="1.0"/>
    </joint>

    <!-- Link 29 - flat on the floor -->
    <link name="link29">
        <visual>
            <geometry>
                <box size="0.03333333333333333 0.013333333333333334 0.025"/>
            </geometry>
            <origin xyz="0.016666666666666666 0 0.0125" rpy="0 0 0"/>
            <material name="purple"/>
        </visual>
        <collision>
            <geometry>
                <box size="0.03333333333333333 0.013333333333333334 0.025"/>
            </geometry>
            <origin xyz="0.016666666666666666 0 0.0125" rpy="0 0 0"/>
        </collision>
        <inertial>
            <mass value="0.907"/>
            <origin xyz="0.016666666666666666 0 0.0125" rpy="0 0 0"/>
            <inertia ixx="0.000061" ixy="0" ixz="0" iyy="0.000131" iyz="0" izz="0.000097"/>
        </inertial>
    </link>

    <!-- Joint 30: link29 to link30 (Revolute around Z-axis) -->
    <joint name="joint30" type="revolute">
        <parent link="link29"/>
        <child link="link30"/>
        <origin xyz="0.03333333333333333 0 0" rpy="0 0 0"/>
        <axis xyz="0 0 1"/>
        <limit lower="-3.14" upper="3.14" effort="6.666666666666667" velocity="1.0"/>
    </joint>

    <!-- Link 30 - flat on the floor -->
    <link name="link30">
        <visual>
            <geometry>
                <box size="0.03333333333333333 0.013333333333333334 0.025"/>
            </geometry>
            <origin xyz="0.016666666666666666 0 0.0125" rpy="0 0 0"/>
            <material name="cyan"/>
        </visual>
        <collision>
            <geometry>
                <box size="0.03333333333333333 0.013333333333333334 0.025"/>
            </geometry>
            <origin xyz="0.016666666666666666 0 0.0125" rpy="0 0 0"/>
        </collision>
        <inertial>
            <mass value="0.903"/>
            <origin xyz="0.016666666666666666 0 0.0125" rpy="0 0 0"/>
            <inertia ixx="0.000060" ixy="0" ixz="0" iyy="0.000131" iyz="0" izz="0.000097"/>
        </inertial>
    </link>

    <!-- End Effector -->
    <joint name="joint31" type="fixed">
        <parent link="link30"/>
        <child link="end_effector"/>
        <origin xyz="0.03333333333333333 0 0.0125" rpy="0 0 0"/>
    </joint>

    <link name="end_effector">
        <visual>
            <geometry>
                <cylinder radius="0.006666666666666667" length="0.025"/>
            </geometry>
            <material name="grey"/>
        </visual>
        <collision>
            <geometry>
                <cylinder radius="0.006666666666666667" length="0.025"/>
            </geometry>
        </collision>
        <inertial>
            <mass value="0.1"/>
            <inertia ixx="0.00001" ixy="0" ixz="0" iyy="0.00001" iyz="0" izz="0.00001"/>
        </inertial>
    </link>
</robot>
