<?xml version="1.0"?>
<robot name="planar_20_dof_robot">
    <!-- Materials -->
    <material name="blue">
        <color rgba="0.0 0.0 0.8 1.0"/>
    </material>
    <material name="red">
        <color rgba="0.8 0.0 0.0 1.0"/>
    </material>
    <material name="green">
        <color rgba="0.0 0.8 0.0 1.0"/>
    </material>
    <material name="yellow">
        <color rgba="0.8 0.8 0.0 1.0"/>
    </material>
    <material name="purple">
        <color rgba="0.8 0.0 0.8 1.0"/>
    </material>
    <material name="cyan">
        <color rgba="0.0 0.8 0.8 1.0"/>
    </material>
    <material name="orange">
        <color rgba="1.0 0.5 0.0 1.0"/>
    </material>
    <material name="grey">
        <color rgba="0.5 0.5 0.5 1.0"/>
    </material>

    <!-- Base Link - flat on the floor -->
    <link name="base_link">
        <visual>
            <geometry>
                <box size="0.1 0.1 0.025"/>
            </geometry>
            <origin xyz="0 0 0.0125" rpy="0 0 0"/>
            <material name="grey"/>
        </visual>
        <collision>
            <geometry>
                <box size="0.1 0.1 0.025"/>
            </geometry>
            <origin xyz="0 0 0.0125" rpy="0 0 0"/>
        </collision>
        <inertial>
            <mass value="1.0"/>
            <origin xyz="0 0 0.0125" rpy="0 0 0"/>
            <inertia 
                ixx="0.0008854166666666668" 
                ixy="0" ixz="0" 
                iyy="0.0008854166666666668" 
                iyz="0" 
                izz="0.001666666666666667"/>
        </inertial>
    </link>

    <!-- Joint 1: base_link to link1 (Revolute around Z-axis) -->
    <joint name="joint1" type="revolute">
        <parent link="base_link"/>
        <child link="link1"/>
        <origin xyz="0.05 0 0" rpy="0 0 0"/>
        <axis xyz="0 0 1"/>
        <limit lower="-3.14" upper="3.14" effort="100" velocity="1.0"/>
    </joint>

    <!-- Link 1 - flat on the floor -->
    <link name="link1">
        <visual>
            <geometry>
                <box size="0.05 0.020000000000000004 0.025"/>
            </geometry>
            <origin xyz="0.025 0 0.0125" rpy="0 0 0"/>
            <material name="blue"/>
        </visual>
        <collision>
            <geometry>
                <box size="0.05 0.020000000000000004 0.025"/>
            </geometry>
            <origin xyz="0.025 0 0.0125" rpy="0 0 0"/>
        </collision>
        <inertial>
            <mass value="1.000"/>
            <origin xyz="0.025 0 0.0125" rpy="0 0 0"/>
            <inertia ixx="0.000085" ixy="0" ixz="0" iyy="0.000260" iyz="0" izz="0.000242"/>
        </inertial>
    </link>

    <!-- Joint 2: link1 to link2 (Revolute around Z-axis) -->
    <joint name="joint2" type="revolute">
        <parent link="link1"/>
        <child link="link2"/>
        <origin xyz="0.05 0 0" rpy="0 0 0"/>
        <axis xyz="0 0 1"/>
        <limit lower="-3.14" upper="3.14" effort="100.0" velocity="1.0"/>
    </joint>

    <!-- Link 2 - flat on the floor -->
    <link name="link2">
        <visual>
            <geometry>
                <box size="0.05 0.020000000000000004 0.025"/>
            </geometry>
            <origin xyz="0.025 0 0.0125" rpy="0 0 0"/>
            <material name="red"/>
        </visual>
        <collision>
            <geometry>
                <box size="0.05 0.020000000000000004 0.025"/>
            </geometry>
            <origin xyz="0.025 0 0.0125" rpy="0 0 0"/>
        </collision>
        <inertial>
            <mass value="0.995"/>
            <origin xyz="0.025 0 0.0125" rpy="0 0 0"/>
            <inertia ixx="0.000085" ixy="0" ixz="0" iyy="0.000259" iyz="0" izz="0.000240"/>
        </inertial>
    </link>

    <!-- Joint 3: link2 to link3 (Revolute around Z-axis) -->
    <joint name="joint3" type="revolute">
        <parent link="link2"/>
        <child link="link3"/>
        <origin xyz="0.05 0 0" rpy="0 0 0"/>
        <axis xyz="0 0 1"/>
        <limit lower="-3.14" upper="3.14" effort="66.66666666666667" velocity="1.0"/>
    </joint>

    <!-- Link 3 - flat on the floor -->
    <link name="link3">
        <visual>
            <geometry>
                <box size="0.05 0.020000000000000004 0.025"/>
            </geometry>
            <origin xyz="0.025 0 0.0125" rpy="0 0 0"/>
            <material name="green"/>
        </visual>
        <collision>
            <geometry>
                <box size="0.05 0.020000000000000004 0.025"/>
            </geometry>
            <origin xyz="0.025 0 0.0125" rpy="0 0 0"/>
        </collision>
        <inertial>
            <mass value="0.990"/>
            <origin xyz="0.025 0 0.0125" rpy="0 0 0"/>
            <inertia ixx="0.000085" ixy="0" ixz="0" iyy="0.000258" iyz="0" izz="0.000239"/>
        </inertial>
    </link>

    <!-- Joint 4: link3 to link4 (Revolute around Z-axis) -->
    <joint name="joint4" type="revolute">
        <parent link="link3"/>
        <child link="link4"/>
        <origin xyz="0.05 0 0" rpy="0 0 0"/>
        <axis xyz="0 0 1"/>
        <limit lower="-3.14" upper="3.14" effort="50.0" velocity="1.0"/>
    </joint>

    <!-- Link 4 - flat on the floor -->
    <link name="link4">
        <visual>
            <geometry>
                <box size="0.05 0.020000000000000004 0.025"/>
            </geometry>
            <origin xyz="0.025 0 0.0125" rpy="0 0 0"/>
            <material name="yellow"/>
        </visual>
        <collision>
            <geometry>
                <box size="0.05 0.020000000000000004 0.025"/>
            </geometry>
            <origin xyz="0.025 0 0.0125" rpy="0 0 0"/>
        </collision>
        <inertial>
            <mass value="0.985"/>
            <origin xyz="0.025 0 0.0125" rpy="0 0 0"/>
            <inertia ixx="0.000084" ixy="0" ixz="0" iyy="0.000257" iyz="0" izz="0.000238"/>
        </inertial>
    </link>

    <!-- Joint 5: link4 to link5 (Revolute around Z-axis) -->
    <joint name="joint5" type="revolute">
        <parent link="link4"/>
        <child link="link5"/>
        <origin xyz="0.05 0 0" rpy="0 0 0"/>
        <axis xyz="0 0 1"/>
        <limit lower="-3.14" upper="3.14" effort="40.0" velocity="1.0"/>
    </joint>

    <!-- Link 5 - flat on the floor -->
    <link name="link5">
        <visual>
            <geometry>
                <box size="0.05 0.020000000000000004 0.025"/>
            </geometry>
            <origin xyz="0.025 0 0.0125" rpy="0 0 0"/>
            <material name="purple"/>
        </visual>
        <collision>
            <geometry>
                <box size="0.05 0.020000000000000004 0.025"/>
            </geometry>
            <origin xyz="0.025 0 0.0125" rpy="0 0 0"/>
        </collision>
        <inertial>
            <mass value="0.980"/>
            <origin xyz="0.025 0 0.0125" rpy="0 0 0"/>
            <inertia ixx="0.000084" ixy="0" ixz="0" iyy="0.000255" iyz="0" izz="0.000237"/>
        </inertial>
    </link>

    <!-- Joint 6: link5 to link6 (Revolute around Z-axis) -->
    <joint name="joint6" type="revolute">
        <parent link="link5"/>
        <child link="link6"/>
        <origin xyz="0.05 0 0" rpy="0 0 0"/>
        <axis xyz="0 0 1"/>
        <limit lower="-3.14" upper="3.14" effort="33.333333333333336" velocity="1.0"/>
    </joint>

    <!-- Link 6 - flat on the floor -->
    <link name="link6">
        <visual>
            <geometry>
                <box size="0.05 0.020000000000000004 0.025"/>
            </geometry>
            <origin xyz="0.025 0 0.0125" rpy="0 0 0"/>
            <material name="cyan"/>
        </visual>
        <collision>
            <geometry>
                <box size="0.05 0.020000000000000004 0.025"/>
            </geometry>
            <origin xyz="0.025 0 0.0125" rpy="0 0 0"/>
        </collision>
        <inertial>
            <mass value="0.975"/>
            <origin xyz="0.025 0 0.0125" rpy="0 0 0"/>
            <inertia ixx="0.000083" ixy="0" ixz="0" iyy="0.000254" iyz="0" izz="0.000236"/>
        </inertial>
    </link>

    <!-- Joint 7: link6 to link7 (Revolute around Z-axis) -->
    <joint name="joint7" type="revolute">
        <parent link="link6"/>
        <child link="link7"/>
        <origin xyz="0.05 0 0" rpy="0 0 0"/>
        <axis xyz="0 0 1"/>
        <limit lower="-3.14" upper="3.14" effort="28.571428571428573" velocity="1.0"/>
    </joint>

    <!-- Link 7 - flat on the floor -->
    <link name="link7">
        <visual>
            <geometry>
                <box size="0.05 0.020000000000000004 0.025"/>
            </geometry>
            <origin xyz="0.025 0 0.0125" rpy="0 0 0"/>
            <material name="orange"/>
        </visual>
        <collision>
            <geometry>
                <box size="0.05 0.020000000000000004 0.025"/>
            </geometry>
            <origin xyz="0.025 0 0.0125" rpy="0 0 0"/>
        </collision>
        <inertial>
            <mass value="0.970"/>
            <origin xyz="0.025 0 0.0125" rpy="0 0 0"/>
            <inertia ixx="0.000083" ixy="0" ixz="0" iyy="0.000253" iyz="0" izz="0.000234"/>
        </inertial>
    </link>

    <!-- Joint 8: link7 to link8 (Revolute around Z-axis) -->
    <joint name="joint8" type="revolute">
        <parent link="link7"/>
        <child link="link8"/>
        <origin xyz="0.05 0 0" rpy="0 0 0"/>
        <axis xyz="0 0 1"/>
        <limit lower="-3.14" upper="3.14" effort="25.0" velocity="1.0"/>
    </joint>

    <!-- Link 8 - flat on the floor -->
    <link name="link8">
        <visual>
            <geometry>
                <box size="0.05 0.020000000000000004 0.025"/>
            </geometry>
            <origin xyz="0.025 0 0.0125" rpy="0 0 0"/>
            <material name="grey"/>
        </visual>
        <collision>
            <geometry>
                <box size="0.05 0.020000000000000004 0.025"/>
            </geometry>
            <origin xyz="0.025 0 0.0125" rpy="0 0 0"/>
        </collision>
        <inertial>
            <mass value="0.965"/>
            <origin xyz="0.025 0 0.0125" rpy="0 0 0"/>
            <inertia ixx="0.000082" ixy="0" ixz="0" iyy="0.000251" iyz="0" izz="0.000233"/>
        </inertial>
    </link>

    <!-- Joint 9: link8 to link9 (Revolute around Z-axis) -->
    <joint name="joint9" type="revolute">
        <parent link="link8"/>
        <child link="link9"/>
        <origin xyz="0.05 0 0" rpy="0 0 0"/>
        <axis xyz="0 0 1"/>
        <limit lower="-3.14" upper="3.14" effort="22.22222222222222" velocity="1.0"/>
    </joint>

    <!-- Link 9 - flat on the floor -->
    <link name="link9">
        <visual>
            <geometry>
                <box size="0.05 0.020000000000000004 0.025"/>
            </geometry>
            <origin xyz="0.025 0 0.0125" rpy="0 0 0"/>
            <material name="blue"/>
        </visual>
        <collision>
            <geometry>
                <box size="0.05 0.020000000000000004 0.025"/>
            </geometry>
            <origin xyz="0.025 0 0.0125" rpy="0 0 0"/>
        </collision>
        <inertial>
            <mass value="0.960"/>
            <origin xyz="0.025 0 0.0125" rpy="0 0 0"/>
            <inertia ixx="0.000082" ixy="0" ixz="0" iyy="0.000250" iyz="0" izz="0.000232"/>
        </inertial>
    </link>

    <!-- Joint 10: link9 to link10 (Revolute around Z-axis) -->
    <joint name="joint10" type="revolute">
        <parent link="link9"/>
        <child link="link10"/>
        <origin xyz="0.05 0 0" rpy="0 0 0"/>
        <axis xyz="0 0 1"/>
        <limit lower="-3.14" upper="3.14" effort="20.0" velocity="1.0"/>
    </joint>

    <!-- Link 10 - flat on the floor -->
    <link name="link10">
        <visual>
            <geometry>
                <box size="0.05 0.020000000000000004 0.025"/>
            </geometry>
            <origin xyz="0.025 0 0.0125" rpy="0 0 0"/>
            <material name="red"/>
        </visual>
        <collision>
            <geometry>
                <box size="0.05 0.020000000000000004 0.025"/>
            </geometry>
            <origin xyz="0.025 0 0.0125" rpy="0 0 0"/>
        </collision>
        <inertial>
            <mass value="0.955"/>
            <origin xyz="0.025 0 0.0125" rpy="0 0 0"/>
            <inertia ixx="0.000082" ixy="0" ixz="0" iyy="0.000249" iyz="0" izz="0.000231"/>
        </inertial>
    </link>

    <!-- Joint 11: link10 to link11 (Revolute around Z-axis) -->
    <joint name="joint11" type="revolute">
        <parent link="link10"/>
        <child link="link11"/>
        <origin xyz="0.05 0 0" rpy="0 0 0"/>
        <axis xyz="0 0 1"/>
        <limit lower="-3.14" upper="3.14" effort="18.181818181818183" velocity="1.0"/>
    </joint>

    <!-- Link 11 - flat on the floor -->
    <link name="link11">
        <visual>
            <geometry>
                <box size="0.05 0.020000000000000004 0.025"/>
            </geometry>
            <origin xyz="0.025 0 0.0125" rpy="0 0 0"/>
            <material name="green"/>
        </visual>
        <collision>
            <geometry>
                <box size="0.05 0.020000000000000004 0.025"/>
            </geometry>
            <origin xyz="0.025 0 0.0125" rpy="0 0 0"/>
        </collision>
        <inertial>
            <mass value="0.950"/>
            <origin xyz="0.025 0 0.0125" rpy="0 0 0"/>
            <inertia ixx="0.000081" ixy="0" ixz="0" iyy="0.000247" iyz="0" izz="0.000230"/>
        </inertial>
    </link>

    <!-- Joint 12: link11 to link12 (Revolute around Z-axis) -->
    <joint name="joint12" type="revolute">
        <parent link="link11"/>
        <child link="link12"/>
        <origin xyz="0.05 0 0" rpy="0 0 0"/>
        <axis xyz="0 0 1"/>
        <limit lower="-3.14" upper="3.14" effort="16.666666666666668" velocity="1.0"/>
    </joint>

    <!-- Link 12 - flat on the floor -->
    <link name="link12">
        <visual>
            <geometry>
                <box size="0.05 0.020000000000000004 0.025"/>
            </geometry>
            <origin xyz="0.025 0 0.0125" rpy="0 0 0"/>
            <material name="yellow"/>
        </visual>
        <collision>
            <geometry>
                <box size="0.05 0.020000000000000004 0.025"/>
            </geometry>
            <origin xyz="0.025 0 0.0125" rpy="0 0 0"/>
        </collision>
        <inertial>
            <mass value="0.945"/>
            <origin xyz="0.025 0 0.0125" rpy="0 0 0"/>
            <inertia ixx="0.000081" ixy="0" ixz="0" iyy="0.000246" iyz="0" izz="0.000228"/>
        </inertial>
    </link>

    <!-- Joint 13: link12 to link13 (Revolute around Z-axis) -->
    <joint name="joint13" type="revolute">
        <parent link="link12"/>
        <child link="link13"/>
        <origin xyz="0.05 0 0" rpy="0 0 0"/>
        <axis xyz="0 0 1"/>
        <limit lower="-3.14" upper="3.14" effort="15.384615384615385" velocity="1.0"/>
    </joint>

    <!-- Link 13 - flat on the floor -->
    <link name="link13">
        <visual>
            <geometry>
                <box size="0.05 0.020000000000000004 0.025"/>
            </geometry>
            <origin xyz="0.025 0 0.0125" rpy="0 0 0"/>
            <material name="purple"/>
        </visual>
        <collision>
            <geometry>
                <box size="0.05 0.020000000000000004 0.025"/>
            </geometry>
            <origin xyz="0.025 0 0.0125" rpy="0 0 0"/>
        </collision>
        <inertial>
            <mass value="0.940"/>
            <origin xyz="0.025 0 0.0125" rpy="0 0 0"/>
            <inertia ixx="0.000080" ixy="0" ixz="0" iyy="0.000245" iyz="0" izz="0.000227"/>
        </inertial>
    </link>

    <!-- Joint 14: link13 to link14 (Revolute around Z-axis) -->
    <joint name="joint14" type="revolute">
        <parent link="link13"/>
        <child link="link14"/>
        <origin xyz="0.05 0 0" rpy="0 0 0"/>
        <axis xyz="0 0 1"/>
        <limit lower="-3.14" upper="3.14" effort="14.285714285714286" velocity="1.0"/>
    </joint>

    <!-- Link 14 - flat on the floor -->
    <link name="link14">
        <visual>
            <geometry>
                <box size="0.05 0.020000000000000004 0.025"/>
            </geometry>
            <origin xyz="0.025 0 0.0125" rpy="0 0 0"/>
            <material name="cyan"/>
        </visual>
        <collision>
            <geometry>
                <box size="0.05 0.020000000000000004 0.025"/>
            </geometry>
            <origin xyz="0.025 0 0.0125" rpy="0 0 0"/>
        </collision>
        <inertial>
            <mass value="0.935"/>
            <origin xyz="0.025 0 0.0125" rpy="0 0 0"/>
            <inertia ixx="0.000080" ixy="0" ixz="0" iyy="0.000243" iyz="0" izz="0.000226"/>
        </inertial>
    </link>

    <!-- Joint 15: link14 to link15 (Revolute around Z-axis) -->
    <joint name="joint15" type="revolute">
        <parent link="link14"/>
        <child link="link15"/>
        <origin xyz="0.05 0 0" rpy="0 0 0"/>
        <axis xyz="0 0 1"/>
        <limit lower="-3.14" upper="3.14" effort="13.333333333333334" velocity="1.0"/>
    </joint>

    <!-- Link 15 - flat on the floor -->
    <link name="link15">
        <visual>
            <geometry>
                <box size="0.05 0.020000000000000004 0.025"/>
            </geometry>
            <origin xyz="0.025 0 0.0125" rpy="0 0 0"/>
            <material name="orange"/>
        </visual>
        <collision>
            <geometry>
                <box size="0.05 0.020000000000000004 0.025"/>
            </geometry>
            <origin xyz="0.025 0 0.0125" rpy="0 0 0"/>
        </collision>
        <inertial>
            <mass value="0.930"/>
            <origin xyz="0.025 0 0.0125" rpy="0 0 0"/>
            <inertia ixx="0.000079" ixy="0" ixz="0" iyy="0.000242" iyz="0" izz="0.000225"/>
        </inertial>
    </link>

    <!-- Joint 16: link15 to link16 (Revolute around Z-axis) -->
    <joint name="joint16" type="revolute">
        <parent link="link15"/>
        <child link="link16"/>
        <origin xyz="0.05 0 0" rpy="0 0 0"/>
        <axis xyz="0 0 1"/>
        <limit lower="-3.14" upper="3.14" effort="12.5" velocity="1.0"/>
    </joint>

    <!-- Link 16 - flat on the floor -->
    <link name="link16">
        <visual>
            <geometry>
                <box size="0.05 0.020000000000000004 0.025"/>
            </geometry>
            <origin xyz="0.025 0 0.0125" rpy="0 0 0"/>
            <material name="grey"/>
        </visual>
        <collision>
            <geometry>
                <box size="0.05 0.020000000000000004 0.025"/>
            </geometry>
            <origin xyz="0.025 0 0.0125" rpy="0 0 0"/>
        </collision>
        <inertial>
            <mass value="0.925"/>
            <origin xyz="0.025 0 0.0125" rpy="0 0 0"/>
            <inertia ixx="0.000079" ixy="0" ixz="0" iyy="0.000241" iyz="0" izz="0.000224"/>
        </inertial>
    </link>

    <!-- Joint 17: link16 to link17 (Revolute around Z-axis) -->
    <joint name="joint17" type="revolute">
        <parent link="link16"/>
        <child link="link17"/>
        <origin xyz="0.05 0 0" rpy="0 0 0"/>
        <axis xyz="0 0 1"/>
        <limit lower="-3.14" upper="3.14" effort="11.764705882352942" velocity="1.0"/>
    </joint>

    <!-- Link 17 - flat on the floor -->
    <link name="link17">
        <visual>
            <geometry>
                <box size="0.05 0.020000000000000004 0.025"/>
            </geometry>
            <origin xyz="0.025 0 0.0125" rpy="0 0 0"/>
            <material name="blue"/>
        </visual>
        <collision>
            <geometry>
                <box size="0.05 0.020000000000000004 0.025"/>
            </geometry>
            <origin xyz="0.025 0 0.0125" rpy="0 0 0"/>
        </collision>
        <inertial>
            <mass value="0.920"/>
            <origin xyz="0.025 0 0.0125" rpy="0 0 0"/>
            <inertia ixx="0.000079" ixy="0" ixz="0" iyy="0.000240" iyz="0" izz="0.000222"/>
        </inertial>
    </link>

    <!-- Joint 18: link17 to link18 (Revolute around Z-axis) -->
    <joint name="joint18" type="revolute">
        <parent link="link17"/>
        <child link="link18"/>
        <origin xyz="0.05 0 0" rpy="0 0 0"/>
        <axis xyz="0 0 1"/>
        <limit lower="-3.14" upper="3.14" effort="11.11111111111111" velocity="1.0"/>
    </joint>

    <!-- Link 18 - flat on the floor -->
    <link name="link18">
        <visual>
            <geometry>
                <box size="0.05 0.020000000000000004 0.025"/>
            </geometry>
            <origin xyz="0.025 0 0.0125" rpy="0 0 0"/>
            <material name="red"/>
        </visual>
        <collision>
            <geometry>
                <box size="0.05 0.020000000000000004 0.025"/>
            </geometry>
            <origin xyz="0.025 0 0.0125" rpy="0 0 0"/>
        </collision>
        <inertial>
            <mass value="0.915"/>
            <origin xyz="0.025 0 0.0125" rpy="0 0 0"/>
            <inertia ixx="0.000078" ixy="0" ixz="0" iyy="0.000238" iyz="0" izz="0.000221"/>
        </inertial>
    </link>

    <!-- Joint 19: link18 to link19 (Revolute around Z-axis) -->
    <joint name="joint19" type="revolute">
        <parent link="link18"/>
        <child link="link19"/>
        <origin xyz="0.05 0 0" rpy="0 0 0"/>
        <axis xyz="0 0 1"/>
        <limit lower="-3.14" upper="3.14" effort="10.526315789473685" velocity="1.0"/>
    </joint>

    <!-- Link 19 - flat on the floor -->
    <link name="link19">
        <visual>
            <geometry>
                <box size="0.05 0.020000000000000004 0.025"/>
            </geometry>
            <origin xyz="0.025 0 0.0125" rpy="0 0 0"/>
            <material name="green"/>
        </visual>
        <collision>
            <geometry>
                <box size="0.05 0.020000000000000004 0.025"/>
            </geometry>
            <origin xyz="0.025 0 0.0125" rpy="0 0 0"/>
        </collision>
        <inertial>
            <mass value="0.910"/>
            <origin xyz="0.025 0 0.0125" rpy="0 0 0"/>
            <inertia ixx="0.000078" ixy="0" ixz="0" iyy="0.000237" iyz="0" izz="0.000220"/>
        </inertial>
    </link>

    <!-- Joint 20: link19 to link20 (Revolute around Z-axis) -->
    <joint name="joint20" type="revolute">
        <parent link="link19"/>
        <child link="link20"/>
        <origin xyz="0.05 0 0" rpy="0 0 0"/>
        <axis xyz="0 0 1"/>
        <limit lower="-3.14" upper="3.14" effort="10.0" velocity="1.0"/>
    </joint>

    <!-- Link 20 - flat on the floor -->
    <link name="link20">
        <visual>
            <geometry>
                <box size="0.05 0.020000000000000004 0.025"/>
            </geometry>
            <origin xyz="0.025 0 0.0125" rpy="0 0 0"/>
            <material name="yellow"/>
        </visual>
        <collision>
            <geometry>
                <box size="0.05 0.020000000000000004 0.025"/>
            </geometry>
            <origin xyz="0.025 0 0.0125" rpy="0 0 0"/>
        </collision>
        <inertial>
            <mass value="0.905"/>
            <origin xyz="0.025 0 0.0125" rpy="0 0 0"/>
            <inertia ixx="0.000077" ixy="0" ixz="0" iyy="0.000236" iyz="0" izz="0.000219"/>
        </inertial>
    </link>

    <!-- End Effector -->
    <joint name="joint21" type="fixed">
        <parent link="link20"/>
        <child link="end_effector"/>
        <origin xyz="0.05 0 0.0125" rpy="0 0 0"/>
    </joint>

    <link name="end_effector">
        <visual>
            <geometry>
                <cylinder radius="0.010000000000000002" length="0.025"/>
            </geometry>
            <material name="grey"/>
        </visual>
        <collision>
            <geometry>
                <cylinder radius="0.010000000000000002" length="0.025"/>
            </geometry>
        </collision>
        <inertial>
            <mass value="0.1"/>
            <inertia ixx="0.00001" ixy="0" ixz="0" iyy="0.00001" iyz="0" izz="0.00001"/>
        </inertial>
    </link>
</robot>
